<?xml version="1.0" ?>
<!-- =================================================================================== -->
<!-- |    This document was autogenerated by xacro from /home/li/ros2_ws/install/openarm_description/share/openarm_description/assets/robot/openarm_v2.0/urdf/openarm_v20.urdf.xacro | -->
<!-- |    EDITING THIS FILE BY HAND IS NOT RECOMMENDED                                 | -->
<!-- =================================================================================== -->
<!--
Copyright 2026 Enactic, Inc.
Licensed under the Apache License, Version 2.0 (the "License");
you may not use this file except in compliance with the License.
You may obtain a copy of the License at
    http://www.apache.org/licenses/LICENSE-2.0
Unless required by applicable law or agreed to in writing, software
distributed under the License is distributed on an "AS IS" BASIS,
WITHOUT WARRANTIES OR CONDITIONS OF ANY KIND, either express or implied.
See the License for the specific language governing permissions and
limitations under the License.
-->
<robot name="openarm_v20">
  <link name="world"/>
  <link name="openarm_body_link0">
    <visual name="openarm_body_link0_visual">
      <origin rpy="0.0 0.0 0.0" xyz="0.0 0.0 0.0"/>
      <geometry>
        <mesh filename="package://openarm_description/assets/robot/openarm_v2.0/meshes/body/visual/body_link0.dae" scale="0.001 0.001 0.001"/>
      </geometry>
      <material name="openarm_body_link0_material">
        <color rgba="0.752941176470588 0.752941176470588 0.752941176470588 1"/>
      </material>
    </visual>
    <collision name="openarm_body_link0_collision">
      <origin rpy="0.0 0.0 0.0" xyz="0.0 0.0 0.0"/>
      <geometry>
        <mesh filename="package://openarm_description/assets/robot/openarm_v2.0/meshes/body/collision/body_link0_symp.stl" scale="0.001 0.001 0.001"/>
      </geometry>
    </collision>
    <inertial>
      <origin rpy="0 0 0" xyz="0 0 0"/>
      <mass value="13.89"/>
      <inertia ixx="1.653" ixy="0.0" ixz="0.0" iyy="1.653" iyz="0.0" izz="0.051"/>
    </inertial>
  </link>
  <joint name="openarm_body_link0_mount_joint" type="fixed">
    <origin rpy="0.0 0.0 0.0" xyz="0.0 0.0 0.0"/>
    <parent link="world"/>
    <child link="openarm_body_link0"/>
  </joint>
  <link name="openarm_left_base_link">
    <visual name="openarm_left_base_link_visual">
      <origin rpy="0 0 0" xyz="0 0 0"/>
      <geometry>
        <mesh filename="package://openarm_description/assets/robot/openarm_v2.0/meshes/arm/visual/base_link.dae" scale="1 -1 1"/>
      </geometry>
      <material name="openarm_left_base_link_material">
        <color rgba="0.752941176470588 0.752941176470588 0.752941176470588 1"/>
      </material>
    </visual>
    <collision name="openarm_left_base_link_collision">
      <origin rpy="0 0 0" xyz="0 0 0"/>
      <geometry>
        <mesh filename="package://openarm_description/assets/robot/openarm_v2.0/meshes/arm/collision/base_link.stl" scale="1 -1 1"/>
      </geometry>
    </collision>
    <inertial>
      <origin rpy="0 0 0" xyz="0.00253123748061566 0.0258185540330169 2.70658291858903e-05"/>
      <mass value="1.1432284943239561"/>
      <inertia ixx="0.00113607806226198" ixy="-3.81487993180929e-07" ixz="1.09161247709715e-08" iyy="0.00159935208714031" iyz="-2.7521421737084e-08" izz="0.000750541980863571"/>
    </inertial>
  </link>
  <joint name="openarm_left_base_link_mount_joint" type="fixed">
    <origin rpy="0.0 0.0 0.0" xyz="0.0 0.031 0.698"/>
    <parent link="openarm_body_link0"/>
    <child link="openarm_left_base_link"/>
  </joint>
  <link name="openarm_left_link1">
    <visual name="openarm_left_link1_visual">
      <origin rpy="0 0 0" xyz="0 0 0"/>
      <geometry>
        <mesh filename="package://openarm_description/assets/robot/openarm_v2.0/meshes/arm/visual/link1.dae" scale="1 -1 1"/>
      </geometry>
      <material name="openarm_left_link1_material">
        <color rgba="0.752941176470588 0.752941176470588 0.752941176470588 1"/>
      </material>
    </visual>
    <collision name="openarm_left_link1_collision">
      <origin rpy="0 0 0" xyz="0 0 0"/>
      <geometry>
        <mesh filename="package://openarm_description/assets/robot/openarm_v2.0/meshes/arm/collision/link1.stl" scale="1 -1 1"/>
      </geometry>
    </collision>
    <inertial>
      <origin rpy="0 0 0" xyz="-0.0009684557444415987 0.04435347020626068 -0.0002270662662340328"/>
      <mass value="1.1500003337860107"/>
      <inertia ixx="0.0011367146275865596" ixy="-1.0079079618043877e-05" ixz="2.6444735508303704e-06" iyy="0.0008052999195037867" iyz="1.8284625306761895e-06" izz="0.0006738855249346595"/>
    </inertial>
  </link>
  <joint name="openarm_left_joint1" type="revolute">
    <origin rpy="0 0 0" xyz="0 0.0625 0"/>
    <parent link="openarm_left_base_link"/>
    <child link="openarm_left_link1"/>
    <axis xyz="0 1 0"/>
    <limit effort="40" lower="-3.4907" upper="1.3963" velocity="16.755"/>
  </joint>
  <link name="openarm_left_link2">
    <visual name="openarm_left_link2_visual">
      <origin rpy="0 0 0" xyz="0 0 0"/>
      <geometry>
        <mesh filename="package://openarm_description/assets/robot/openarm_v2.0/meshes/arm/visual/link2.dae" scale="1 -1 1"/>
      </geometry>
      <material name="openarm_left_link2_material">
        <color rgba="0.752941176470588 0.752941176470588 0.752941176470588 1"/>
      </material>
    </visual>
    <collision name="openarm_left_link2_collision">
      <origin rpy="0 0 0" xyz="0 0 0"/>
      <geometry>
        <mesh filename="package://openarm_description/assets/robot/openarm_v2.0/meshes/arm/collision/link2.stl" scale="1 -1 1"/>
      </geometry>
    </collision>
    <inertial>
      <origin rpy="0 0 0" xyz="-0.02501162514090538 -0.000938087294343859 -0.030767099931836128"/>
      <mass value="0.2833385169506073"/>
      <inertia ixx="0.00015570692536483682" ixy="-6.669784880496628e-08" ixz="5.340448363813931e-06" iyy="0.00011469650928940006" iyz="-5.552288761598194e-07" izz="8.297089697712e-05"/>
    </inertial>
  </link>
  <joint name="openarm_left_joint2" type="revolute">
    <origin rpy="0 0 0" xyz="0 0.0600000000000001 0"/>
    <parent link="openarm_left_link1"/>
    <child link="openarm_left_link2"/>
    <axis xyz="-1 0 0"/>
    <limit effort="40" lower="-3.3161" upper="0.17453" velocity="16.755"/>
  </joint>
  <link name="openarm_left_link3">
    <visual name="openarm_left_link3_visual">
      <origin rpy="0 0 0" xyz="0 0 0"/>
      <geometry>
        <mesh filename="package://openarm_description/assets/robot/openarm_v2.0/meshes/arm/visual/link3.dae" scale="1 1 1"/>
      </geometry>
      <material name="openarm_left_link3_material">
        <color rgba="0.752941176470588 0.752941176470588 0.752941176470588 1"/>
      </material>
    </visual>
    <collision name="openarm_left_link3_collision">
      <origin rpy="0 0 0" xyz="0 0 0"/>
      <geometry>
        <mesh filename="package://openarm_description/assets/robot/openarm_v2.0/meshes/arm/collision/link3.stl" scale="1 1 1"/>
      </geometry>
    </collision>
    <inertial>
      <origin rpy="0 0 0" xyz="-0.007416668813675642 0.0018997029401361942 -0.11574232578277588"/>
      <mass value="1.0966242551803589"/>
      <inertia ixx="0.0015163142414272301" ixy="-1.1875947879595944e-06" ixz="-9.390963500334839e-05" iyy="0.0013368010487385378" iyz="-1.3708079994726228e-05" izz="0.0006197750082458824"/>
    </inertial>
  </link>
  <joint name="openarm_left_joint3" type="revolute">
    <origin rpy="0 0 0" xyz="0 0 -0.0662500000000008"/>
    <parent link="openarm_left_link2"/>
    <child link="openarm_left_link3"/>
    <axis xyz="0 0 -1"/>
    <limit effort="27" lower="-1.5708" upper="1.5708" velocity="5.4454"/>
  </joint>
  <link name="openarm_left_link4">
    <visual name="openarm_left_link4_visual">
      <origin rpy="0 0 0" xyz="0 0 0"/>
      <geometry>
        <mesh filename="package://openarm_description/assets/robot/openarm_v2.0/meshes/arm/visual/link4.dae" scale="1 1 1"/>
      </geometry>
      <material name="openarm_left_link4_material">
        <color rgba="0.752941176470588 0.752941176470588 0.752941176470588 1"/>
      </material>
    </visual>
    <collision name="openarm_left_link4_collision">
      <origin rpy="0 0 0" xyz="0 0 0"/>
      <geometry>
        <mesh filename="package://openarm_description/assets/robot/openarm_v2.0/meshes/arm/collision/link4.stl" scale="1 1 1"/>
      </geometry>
    </collision>
    <inertial>
      <origin rpy="0 0 0" xyz="-0.003996944520622492 -0.000492816383484751 -0.055598314851522446"/>
      <mass value="0.550157368183136"/>
      <inertia ixx="0.0005113978223608661" ixy="5.013847732708921e-06" ixz="2.5120111701945223e-06" iyy="0.0004742019826035446" iyz="6.838554598982083e-06" izz="0.0002561247291320234"/>
    </inertial>
  </link>
  <joint name="openarm_left_joint4" type="revolute">
    <origin rpy="0 0 0" xyz="0 0 -0.15375"/>
    <parent link="openarm_left_link3"/>
    <child link="openarm_left_link4"/>
    <axis xyz="0 -1 0"/>
    <limit effort="27" lower="0" upper="2.4435" velocity="5.4454"/>
  </joint>
  <link name="openarm_left_link5">
    <visual name="openarm_left_link5_visual">
      <origin rpy="0 0 0" xyz="0 0 0"/>
      <geometry>
        <mesh filename="package://openarm_description/assets/robot/openarm_v2.0/meshes/arm/visual/link5.dae" scale="1 -1 1"/>
      </geometry>
      <material name="openarm_left_link5_material">
        <color rgba="0.752941176470588 0.752941176470588 0.752941176470588 1"/>
      </material>
    </visual>
    <collision name="openarm_left_link5_collision">
      <origin rpy="0 0 0" xyz="0 0 0"/>
      <geometry>
        <mesh filename="package://openarm_description/assets/robot/openarm_v2.0/meshes/arm/collision/link5.stl" scale="1 -1 1"/>
      </geometry>
    </collision>
    <inertial>
      <origin rpy="0 0 0" xyz="-0.0012892766389995813 0.00024264087551273406 -0.04764603450894356"/>
      <mass value="0.5030861496925354"/>
      <inertia ixx="0.000296797674109975" ixy="-4.163899388611228e-06" ixz="5.320538210594659e-06" iyy="0.00035464038671783986" iyz="8.971382500025113e-07" izz="0.00018198116071283747"/>
    </inertial>
  </link>
  <joint name="openarm_left_joint5" type="revolute">
    <origin rpy="0 0 0" xyz="0 0 -0.0955000000000005"/>
    <parent link="openarm_left_link4"/>
    <child link="openarm_left_link5"/>
    <axis xyz="0 0 -1"/>
    <limit effort="7" lower="-1.5708" upper="1.5708" velocity="20.944"/>
  </joint>
  <link name="openarm_left_link6">
    <visual name="openarm_left_link6_visual">
      <origin rpy="0 0 0" xyz="0 0 0"/>
      <geometry>
        <mesh filename="package://openarm_description/assets/robot/openarm_v2.0/meshes/arm/visual/link6.dae" scale="1 -1 1"/>
      </geometry>
      <material name="openarm_left_link6_material">
        <color rgba="0.752941176470588 0.752941176470588 0.752941176470588 1"/>
      </material>
    </visual>
    <collision name="openarm_left_link6_collision">
      <origin rpy="0 0 0" xyz="0 0 0"/>
      <geometry>
        <mesh filename="package://openarm_description/assets/robot/openarm_v2.0/meshes/arm/collision/link6.stl" scale="1 -1 1"/>
      </geometry>
    </collision>
    <inertial>
      <origin rpy="0 0 0" xyz="-0.0002560609136708081 -0.001021706615574658 -0.0012552272528409958"/>
      <mass value="0.48467960953712463"/>
      <inertia ixx="0.0001850871073800258" ixy="-1.2683694789849103e-08" ixz="2.6280862754997384e-07" iyy="0.00014022360718755702" iyz="-1.8853219678300488e-06" izz="0.0001385493316653775"/>
    </inertial>
  </link>
  <joint name="openarm_left_joint6" type="revolute">
    <origin rpy="0 0 0" xyz="0 0 -0.120499999999998"/>
    <parent link="openarm_left_link5"/>
    <child link="openarm_left_link6"/>
    <axis xyz="0 -1 0"/>
    <limit effort="7" lower="-0.7854" upper="0.7854" velocity="20.944"/>
  </joint>
  <joint name="openarm_left_joint7" type="revolute">
    <origin rpy="0 0 0" xyz="0 0 0"/>
    <parent link="openarm_left_link6"/>
    <child link="openarm_left_ee_base_link"/>
    <axis xyz="1 0 0"/>
    <limit effort="7" lower="-1.5708" upper="1.5708" velocity="20.944"/>
  </joint>
  <!-- The base link is emitted inline because its naming and frame-shift behavior differ from the finger links. -->
  <link name="openarm_left_ee_base_link">
    <visual name="openarm_left_ee_base_link_visual">
      <origin rpy="0.0 -0.0 0.0" xyz="0.0205 -0.0 0.0"/>
      <geometry>
        <mesh filename="package://openarm_description/assets/end_effector/pinch_gripper/meshes/visual/ee_base_link.dae" scale="1 -1 1"/>
      </geometry>
      <material name="openarm_left_ee_base_link_material">
        <color rgba="0.752941176470588 0.752941176470588 0.752941176470588 1"/>
      </material>
    </visual>
    <collision name="openarm_left_ee_base_link_collision">
      <origin rpy="0.0 -0.0 0.0" xyz="0.0205 -0.0 0.0"/>
      <geometry>
        <mesh filename="package://openarm_description/assets/end_effector/pinch_gripper/meshes/collision/ee_base_link.stl" scale="1 -1 1"/>
      </geometry>
    </collision>
    <inertial>
      <origin rpy="0.0 -0.0 0.0" xyz="0.013461275026202202 -0.008792271837592125 -0.06151682138442993"/>
      <mass value="0.6586037874221802"/>
      <inertia ixx="0.00022638765367662258" ixy="-2.561378390037678e-06" ixz="3.7455989076146763e-06" iyy="0.00016121245355352502" iyz="9.08778435797892e-06" izz="0.00016977814330262694"/>
    </inertial>
  </link>
  <link name="openarm_left_ee_link1">
    <visual name="openarm_left_ee_link1_visual">
      <origin rpy="0 0 0" xyz="0 0 0"/>
      <geometry>
        <mesh filename="package://openarm_description/assets/end_effector/pinch_gripper/meshes/visual/finger_inner.dae" scale="1 -1 1"/>
      </geometry>
      <material name="openarm_left_ee_link1_material">
        <color rgba="0.752941176470588 0.752941176470588 0.752941176470588 1"/>
      </material>
    </visual>
    <collision name="openarm_left_ee_link1_collision">
      <origin rpy="0 0 0" xyz="0 0 0"/>
      <geometry>
        <mesh filename="package://openarm_description/assets/end_effector/pinch_gripper/meshes/collision/finger_inner.stl" scale="1 -1 1"/>
      </geometry>
    </collision>
    <inertial>
      <origin rpy="0 0 0" xyz="-0.012410171329975128 -0.001626630430109799 -0.024798203259706497"/>
      <mass value="0.1407792717218399"/>
      <inertia ixx="3.6104128567041486e-05" ixy="-1.3294860993897662e-06" ixz="7.123210485378218e-06" iyy="3.623159072928168e-05" iyz="3.5064725231529553e-06" izz="1.7550901619568176e-05"/>
    </inertial>
  </link>
  <link name="openarm_left_ee_link2">
    <visual name="openarm_left_ee_link2_visual">
      <origin rpy="0 0 0" xyz="0 0 0"/>
      <geometry>
        <mesh filename="package://openarm_description/assets/end_effector/pinch_gripper/meshes/visual/finger_outer.dae" scale="1 -1 1"/>
      </geometry>
      <material name="openarm_left_ee_link2_material">
        <color rgba="0.752941176470588 0.752941176470588 0.752941176470588 1"/>
      </material>
    </visual>
    <collision name="openarm_left_ee_link2_collision">
      <origin rpy="0 0 0" xyz="0 0 0"/>
      <geometry>
        <mesh filename="package://openarm_description/assets/end_effector/pinch_gripper/meshes/collision/finger_outer.stl" scale="1 -1 1"/>
      </geometry>
    </collision>
    <inertial>
      <origin rpy="0 0 0" xyz="-0.012705761939287186 0.0019605811685323715 -0.027511516585946083"/>
      <mass value="0.12671074271202087"/>
      <inertia ixx="3.4385259678519875e-05" ixy="1.3522958560770914e-06" ixz="7.072086433340861e-06" iyy="3.514367461484924e-05" iyz="-3.5687329346314576e-06" izz="1.6635469574515654e-05"/>
    </inertial>
  </link>
  <joint name="openarm_left_finger_joint1" type="revolute">
    <origin rpy="0.0 -0.0 0.0" xyz="-0.0014300000000005003 -0.0180000000000009 -0.0680000000000174"/>
    <parent link="openarm_left_ee_base_link"/>
    <child link="openarm_left_ee_link1"/>
    <axis xyz="-1 0 0"/>
    <limit effort="7" lower="0" upper="0.7854" velocity="5"/>
  </joint>
  <joint name="openarm_left_finger_joint2" type="revolute">
    <origin rpy="0.0 -0.0 0.0" xyz="-0.0014300000000005003 0.0180000000000012 -0.0680000000000215"/>
    <parent link="openarm_left_ee_base_link"/>
    <child link="openarm_left_ee_link2"/>
    <axis xyz="1 0 0"/>
    <limit effort="7" lower="0" upper="0.7854" velocity="5"/>
    <mimic joint="openarm_left_finger_joint1" multiplier="1" offset="0"/>
  </joint>
  <link name="openarm_right_base_link">
    <visual name="openarm_right_base_link_visual">
      <origin rpy="0 0 0" xyz="0 0 0"/>
      <geometry>
        <mesh filename="package://openarm_description/assets/robot/openarm_v2.0/meshes/arm/visual/base_link.dae" scale="1 1 1"/>
      </geometry>
      <material name="openarm_right_base_link_material">
        <color rgba="0.752941176470588 0.752941176470588 0.752941176470588 1"/>
      </material>
    </visual>
    <collision name="openarm_right_base_link_collision">
      <origin rpy="0 0 0" xyz="0 0 0"/>
      <geometry>
        <mesh filename="package://openarm_description/assets/robot/openarm_v2.0/meshes/arm/collision/base_link.stl" scale="1 1 1"/>
      </geometry>
    </collision>
    <inertial>
      <origin rpy="0 0 0" xyz="0.00253123748061566 -0.0258185540330169 2.70658291858903e-05"/>
      <mass value="1.1432284943239561"/>
      <inertia ixx="0.00113607806226198" ixy="3.81487993180929e-07" ixz="1.09161247709715e-08" iyy="0.00159935208714031" iyz="2.7521421737084e-08" izz="0.000750541980863571"/>
    </inertial>
  </link>
  <joint name="openarm_right_base_link_mount_joint" type="fixed">
    <origin rpy="0.0 0.0 0.0" xyz="0.0 -0.031 0.698"/>
    <parent link="openarm_body_link0"/>
    <child link="openarm_right_base_link"/>
  </joint>
  <link name="openarm_right_link1">
    <visual name="openarm_right_link1_visual">
      <origin rpy="0 0 0" xyz="0 0 0"/>
      <geometry>
        <mesh filename="package://openarm_description/assets/robot/openarm_v2.0/meshes/arm/visual/link1.dae" scale="1 1 1"/>
      </geometry>
      <material name="openarm_right_link1_material">
        <color rgba="0.752941176470588 0.752941176470588 0.752941176470588 1"/>
      </material>
    </visual>
    <collision name="openarm_right_link1_collision">
      <origin rpy="0 0 0" xyz="0 0 0"/>
      <geometry>
        <mesh filename="package://openarm_description/assets/robot/openarm_v2.0/meshes/arm/collision/link1.stl" scale="1 1 1"/>
      </geometry>
    </collision>
    <inertial>
      <origin rpy="0 0 0" xyz="-0.0009684557444415987 -0.04435347020626068 -0.0002270662662340328"/>
      <mass value="1.1500003337860107"/>
      <inertia ixx="0.0011367146275865596" ixy="1.0079079618043877e-05" ixz="2.6444735508303704e-06" iyy="0.0008052999195037867" iyz="-1.8284625306761895e-06" izz="0.0006738855249346595"/>
    </inertial>
  </link>
  <joint name="openarm_right_joint1" type="revolute">
    <origin rpy="0 0 0" xyz="0 -0.0625 0"/>
    <parent link="openarm_right_base_link"/>
    <child link="openarm_right_link1"/>
    <axis xyz="0 -1 0"/>
    <limit effort="40" lower="-1.3963" upper="3.4907" velocity="16.755"/>
  </joint>
  <link name="openarm_right_link2">
    <visual name="openarm_right_link2_visual">
      <origin rpy="0 0 0" xyz="0 0 0"/>
      <geometry>
        <mesh filename="package://openarm_description/assets/robot/openarm_v2.0/meshes/arm/visual/link2.dae" scale="1 1 1"/>
      </geometry>
      <material name="openarm_right_link2_material">
        <color rgba="0.752941176470588 0.752941176470588 0.752941176470588 1"/>
      </material>
    </visual>
    <collision name="openarm_right_link2_collision">
      <origin rpy="0 0 0" xyz="0 0 0"/>
      <geometry>
        <mesh filename="package://openarm_description/assets/robot/openarm_v2.0/meshes/arm/collision/link2.stl" scale="1 1 1"/>
      </geometry>
    </collision>
    <inertial>
      <origin rpy="0 0 0" xyz="-0.02501162514090538 0.000938087294343859 -0.030767099931836128"/>
      <mass value="0.2833385169506073"/>
      <inertia ixx="0.00015570692536483682" ixy="6.669784880496628e-08" ixz="5.340448363813931e-06" iyy="0.00011469650928940006" iyz="5.552288761598194e-07" izz="8.297089697712e-05"/>
    </inertial>
  </link>
  <joint name="openarm_right_joint2" type="revolute">
    <origin rpy="0 0 0" xyz="0 -0.0600000000000001 0"/>
    <parent link="openarm_right_link1"/>
    <child link="openarm_right_link2"/>
    <axis xyz="-1 0 0"/>
    <limit effort="40" lower="-0.17453" upper="3.3161" velocity="16.755"/>
  </joint>
  <link name="openarm_right_link3">
    <visual name="openarm_right_link3_visual">
      <origin rpy="0 0 0" xyz="0 0 0"/>
      <geometry>
        <mesh filename="package://openarm_description/assets/robot/openarm_v2.0/meshes/arm/visual/link3.dae" scale="1 1 1"/>
      </geometry>
      <material name="openarm_right_link3_material">
        <color rgba="0.752941176470588 0.752941176470588 0.752941176470588 1"/>
      </material>
    </visual>
    <collision name="openarm_right_link3_collision">
      <origin rpy="0 0 0" xyz="0 0 0"/>
      <geometry>
        <mesh filename="package://openarm_description/assets/robot/openarm_v2.0/meshes/arm/collision/link3.stl" scale="1 1 1"/>
      </geometry>
    </collision>
    <inertial>
      <origin rpy="0 0 0" xyz="-0.007416668813675642 0.0018997029401361942 -0.11574232578277588"/>
      <mass value="1.0966242551803589"/>
      <inertia ixx="0.0015163142414272301" ixy="-1.1875947879595944e-06" ixz="-9.390963500334839e-05" iyy="0.0013368010487385378" iyz="-1.3708079994726228e-05" izz="0.0006197750082458824"/>
    </inertial>
  </link>
  <joint name="openarm_right_joint3" type="revolute">
    <origin rpy="0 0 0" xyz="0 0 -0.0662500000000008"/>
    <parent link="openarm_right_link2"/>
    <child link="openarm_right_link3"/>
    <axis xyz="0 0 -1"/>
    <limit effort="27" lower="-1.5708" upper="1.5708" velocity="5.4454"/>
  </joint>
  <link name="openarm_right_link4">
    <visual name="openarm_right_link4_visual">
      <origin rpy="0 0 0" xyz="0 0 0"/>
      <geometry>
        <mesh filename="package://openarm_description/assets/robot/openarm_v2.0/meshes/arm/visual/link4.dae" scale="1 1 1"/>
      </geometry>
      <material name="openarm_right_link4_material">
        <color rgba="0.752941176470588 0.752941176470588 0.752941176470588 1"/>
      </material>
    </visual>
    <collision name="openarm_right_link4_collision">
      <origin rpy="0 0 0" xyz="0 0 0"/>
      <geometry>
        <mesh filename="package://openarm_description/assets/robot/openarm_v2.0/meshes/arm/collision/link4.stl" scale="1 1 1"/>
      </geometry>
    </collision>
    <inertial>
      <origin rpy="0 0 0" xyz="-0.003996944520622492 -0.000492816383484751 -0.055598314851522446"/>
      <mass value="0.550157368183136"/>
      <inertia ixx="0.0005113978223608661" ixy="5.013847732708921e-06" ixz="2.5120111701945223e-06" iyy="0.0004742019826035446" iyz="6.838554598982083e-06" izz="0.0002561247291320234"/>
    </inertial>
  </link>
  <joint name="openarm_right_joint4" type="revolute">
    <origin rpy="0 0 0" xyz="0 0 -0.15375"/>
    <parent link="openarm_right_link3"/>
    <child link="openarm_right_link4"/>
    <axis xyz="0 -1 0"/>
    <limit effort="27" lower="0" upper="2.4435" velocity="5.4454"/>
  </joint>
  <link name="openarm_right_link5">
    <visual name="openarm_right_link5_visual">
      <origin rpy="0 0 0" xyz="0 0 0"/>
      <geometry>
        <mesh filename="package://openarm_description/assets/robot/openarm_v2.0/meshes/arm/visual/link5.dae" scale="1 1 1"/>
      </geometry>
      <material name="openarm_right_link5_material">
        <color rgba="0.752941176470588 0.752941176470588 0.752941176470588 1"/>
      </material>
    </visual>
    <collision name="openarm_right_link5_collision">
      <origin rpy="0 0 0" xyz="0 0 0"/>
      <geometry>
        <mesh filename="package://openarm_description/assets/robot/openarm_v2.0/meshes/arm/collision/link5.stl" scale="1 1 1"/>
      </geometry>
    </collision>
    <inertial>
      <origin rpy="0 0 0" xyz="-0.0012892766389995813 -0.00024264087551273406 -0.04764603450894356"/>
      <mass value="0.5030861496925354"/>
      <inertia ixx="0.000296797674109975" ixy="4.163899388611228e-06" ixz="5.320538210594659e-06" iyy="0.00035464038671783986" iyz="-8.971382500025113e-07" izz="0.00018198116071283747"/>
    </inertial>
  </link>
  <joint name="openarm_right_joint5" type="revolute">
    <origin rpy="0 0 0" xyz="0 0 -0.0955000000000005"/>
    <parent link="openarm_right_link4"/>
    <child link="openarm_right_link5"/>
    <axis xyz="0 0 -1"/>
    <limit effort="7" lower="-1.5708" upper="1.5708" velocity="20.944"/>
  </joint>
  <link name="openarm_right_link6">
    <visual name="openarm_right_link6_visual">
      <origin rpy="0 0 0" xyz="0 0 0"/>
      <geometry>
        <mesh filename="package://openarm_description/assets/robot/openarm_v2.0/meshes/arm/visual/link6.dae" scale="1 1 1"/>
      </geometry>
      <material name="openarm_right_link6_material">
        <color rgba="0.752941176470588 0.752941176470588 0.752941176470588 1"/>
      </material>
    </visual>
    <collision name="openarm_right_link6_collision">
      <origin rpy="0 0 0" xyz="0 0 0"/>
      <geometry>
        <mesh filename="package://openarm_description/assets/robot/openarm_v2.0/meshes/arm/collision/link6.stl" scale="1 1 1"/>
      </geometry>
    </collision>
    <inertial>
      <origin rpy="0 0 0" xyz="-0.0002560609136708081 0.001021706615574658 -0.0012552272528409958"/>
      <mass value="0.48467960953712463"/>
      <inertia ixx="0.0001850871073800258" ixy="1.2683694789849103e-08" ixz="2.6280862754997384e-07" iyy="0.00014022360718755702" iyz="1.8853219678300488e-06" izz="0.0001385493316653775"/>
    </inertial>
  </link>
  <joint name="openarm_right_joint6" type="revolute">
    <origin rpy="0 0 0" xyz="0 0 -0.120499999999998"/>
    <parent link="openarm_right_link5"/>
    <child link="openarm_right_link6"/>
    <axis xyz="0 1 0"/>
    <limit effort="7" lower="-0.7854" upper="0.7854" velocity="20.944"/>
  </joint>
  <joint name="openarm_right_joint7" type="revolute">
    <origin rpy="0 0 0" xyz="0 0 0"/>
    <parent link="openarm_right_link6"/>
    <child link="openarm_right_ee_base_link"/>
    <axis xyz="1 0 0"/>
    <limit effort="7" lower="-1.5708" upper="1.5708" velocity="20.944"/>
  </joint>
  <!-- The base link is emitted inline because its naming and frame-shift behavior differ from the finger links. -->
  <link name="openarm_right_ee_base_link">
    <visual name="openarm_right_ee_base_link_visual">
      <origin rpy="0.0 -0.0 0.0" xyz="0.0205 0.0 0.0"/>
      <geometry>
        <mesh filename="package://openarm_description/assets/end_effector/pinch_gripper/meshes/visual/ee_base_link.dae" scale="1 1 1"/>
      </geometry>
      <material name="openarm_right_ee_base_link_material">
        <color rgba="0.752941176470588 0.752941176470588 0.752941176470588 1"/>
      </material>
    </visual>
    <collision name="openarm_right_ee_base_link_collision">
      <origin rpy="0.0 -0.0 0.0" xyz="0.0205 0.0 0.0"/>
      <geometry>
        <mesh filename="package://openarm_description/assets/end_effector/pinch_gripper/meshes/collision/ee_base_link.stl" scale="1 1 1"/>
      </geometry>
    </collision>
    <inertial>
      <origin rpy="0.0 -0.0 0.0" xyz="0.013461275026202202 0.008792271837592125 -0.06151682138442993"/>
      <mass value="0.6586037874221802"/>
      <inertia ixx="0.00022638765367662258" ixy="2.561378390037678e-06" ixz="3.7455989076146763e-06" iyy="0.00016121245355352502" iyz="-9.08778435797892e-06" izz="0.00016977814330262694"/>
    </inertial>
  </link>
  <link name="openarm_right_ee_link1">
    <visual name="openarm_right_ee_link1_visual">
      <origin rpy="0 0 0" xyz="0 0 0"/>
      <geometry>
        <mesh filename="package://openarm_description/assets/end_effector/pinch_gripper/meshes/visual/finger_inner.dae" scale="1 1 1"/>
      </geometry>
      <material name="openarm_right_ee_link1_material">
        <color rgba="0.752941176470588 0.752941176470588 0.752941176470588 1"/>
      </material>
    </visual>
    <collision name="openarm_right_ee_link1_collision">
      <origin rpy="0 0 0" xyz="0 0 0"/>
      <geometry>
        <mesh filename="package://openarm_description/assets/end_effector/pinch_gripper/meshes/collision/finger_inner.stl" scale="1 1 1"/>
      </geometry>
    </collision>
    <inertial>
      <origin rpy="0 0 0" xyz="-0.012410171329975128 0.001626630430109799 -0.024798203259706497"/>
      <mass value="0.1407792717218399"/>
      <inertia ixx="3.6104128567041486e-05" ixy="1.3294860993897662e-06" ixz="7.123210485378218e-06" iyy="3.623159072928168e-05" iyz="-3.5064725231529553e-06" izz="1.7550901619568176e-05"/>
    </inertial>
  </link>
  <link name="openarm_right_ee_link2">
    <visual name="openarm_right_ee_link2_visual">
      <origin rpy="0 0 0" xyz="0 0 0"/>
      <geometry>
        <mesh filename="package://openarm_description/assets/end_effector/pinch_gripper/meshes/visual/finger_outer.dae" scale="1 1 1"/>
      </geometry>
      <material name="openarm_right_ee_link2_material">
        <color rgba="0.752941176470588 0.752941176470588 0.752941176470588 1"/>
      </material>
    </visual>
    <collision name="openarm_right_ee_link2_collision">
      <origin rpy="0 0 0" xyz="0 0 0"/>
      <geometry>
        <mesh filename="package://openarm_description/assets/end_effector/pinch_gripper/meshes/collision/finger_outer.stl" scale="1 1 1"/>
      </geometry>
    </collision>
    <inertial>
      <origin rpy="0 0 0" xyz="-0.012705761939287186 -0.0019605811685323715 -0.027511516585946083"/>
      <mass value="0.12671074271202087"/>
      <inertia ixx="3.4385259678519875e-05" ixy="-1.3522958560770914e-06" ixz="7.072086433340861e-06" iyy="3.514367461484924e-05" iyz="3.5687329346314576e-06" izz="1.6635469574515654e-05"/>
    </inertial>
  </link>
  <joint name="openarm_right_finger_joint1" type="revolute">
    <origin rpy="0.0 -0.0 0.0" xyz="-0.0014300000000005003 0.0180000000000009 -0.0680000000000174"/>
    <parent link="openarm_right_ee_base_link"/>
    <child link="openarm_right_ee_link1"/>
    <axis xyz="-1 0 0"/>
    <limit effort="7" lower="-0.7854" upper="0" velocity="5"/>
  </joint>
  <joint name="openarm_right_finger_joint2" type="revolute">
    <origin rpy="0.0 -0.0 0.0" xyz="-0.0014300000000005003 -0.0180000000000012 -0.0680000000000215"/>
    <parent link="openarm_right_ee_base_link"/>
    <child link="openarm_right_ee_link2"/>
    <axis xyz="1 0 0"/>
    <limit effort="7" lower="-0.7854" upper="0" velocity="5"/>
    <mimic joint="openarm_right_finger_joint1" multiplier="1" offset="0"/>
  </joint>
  <ros2_control name="openarm_left_hardware_interface" type="system">
    <hardware>
      <param name="arm_type">v20</param>
      <plugin>mock_components/GenericSystem</plugin>
      <param name="fake_sensor_commands">False</param>
      <param name="state_following_offset">0.0</param>
    </hardware>
    <joint name="openarm_left_joint1">
      <command_interface name="position"/>
      <command_interface name="velocity"/>
      <command_interface name="effort"/>
      <state_interface name="position">
        <param name="initial_value">0.0</param>
      </state_interface>
      <state_interface name="velocity">
        <param name="initial_value">0.0</param>
      </state_interface>
      <state_interface name="effort">
        <param name="initial_value">0.0</param>
      </state_interface>
    </joint>
    <joint name="openarm_left_joint2">
      <command_interface name="position"/>
      <command_interface name="velocity"/>
      <command_interface name="effort"/>
      <state_interface name="position">
        <param name="initial_value">0.0</param>
      </state_interface>
      <state_interface name="velocity">
        <param name="initial_value">0.0</param>
      </state_interface>
      <state_interface name="effort">
        <param name="initial_value">0.0</param>
      </state_interface>
    </joint>
    <joint name="openarm_left_joint3">
      <command_interface name="position"/>
      <command_interface name="velocity"/>
      <command_interface name="effort"/>
      <state_interface name="position">
        <param name="initial_value">0.0</param>
      </state_interface>
      <state_interface name="velocity">
        <param name="initial_value">0.0</param>
      </state_interface>
      <state_interface name="effort">
        <param name="initial_value">0.0</param>
      </state_interface>
    </joint>
    <joint name="openarm_left_joint4">
      <command_interface name="position"/>
      <command_interface name="velocity"/>
      <command_interface name="effort"/>
      <state_interface name="position">
        <param name="initial_value">0.0</param>
      </state_interface>
      <state_interface name="velocity">
        <param name="initial_value">0.0</param>
      </state_interface>
      <state_interface name="effort">
        <param name="initial_value">0.0</param>
      </state_interface>
    </joint>
    <joint name="openarm_left_joint5">
      <command_interface name="position"/>
      <command_interface name="velocity"/>
      <command_interface name="effort"/>
      <state_interface name="position">
        <param name="initial_value">0.0</param>
      </state_interface>
      <state_interface name="velocity">
        <param name="initial_value">0.0</param>
      </state_interface>
      <state_interface name="effort">
        <param name="initial_value">0.0</param>
      </state_interface>
    </joint>
    <joint name="openarm_left_joint6">
      <command_interface name="position"/>
      <command_interface name="velocity"/>
      <command_interface name="effort"/>
      <state_interface name="position">
        <param name="initial_value">0.0</param>
      </state_interface>
      <state_interface name="velocity">
        <param name="initial_value">0.0</param>
      </state_interface>
      <state_interface name="effort">
        <param name="initial_value">0.0</param>
      </state_interface>
    </joint>
    <joint name="openarm_left_joint7">
      <command_interface name="position"/>
      <command_interface name="velocity"/>
      <command_interface name="effort"/>
      <state_interface name="position">
        <param name="initial_value">0.0</param>
      </state_interface>
      <state_interface name="velocity">
        <param name="initial_value">0.0</param>
      </state_interface>
      <state_interface name="effort">
        <param name="initial_value">0.0</param>
      </state_interface>
    </joint>
    <joint name="openarm_left_finger_joint1">
      <command_interface name="position"/>
      <command_interface name="velocity"/>
      <command_interface name="effort"/>
      <state_interface name="position">
        <param name="initial_value">0.0</param>
      </state_interface>
      <state_interface name="velocity">
        <param name="initial_value">0.0</param>
      </state_interface>
      <state_interface name="effort">
        <param name="initial_value">0.0</param>
      </state_interface>
    </joint>
    <!-- <joint name="openarm_${left_arm_prefix}finger_joint2">
        <param name="mimic">openarm_${left_arm_prefix}finger_joint1</param>
        <param name="multiplier">${left_finger_mimic_multiplier}</param>
        <command_interface name="position"/>
        <state_interface name="position">
          <param name="initial_value">0.0</param>
        </state_interface>
      </joint> -->
  </ros2_control>
  <ros2_control name="openarm_right_hardware_interface" type="system">
    <hardware>
      <param name="arm_type">v20</param>
      <plugin>mock_components/GenericSystem</plugin>
      <param name="fake_sensor_commands">False</param>
      <param name="state_following_offset">0.0</param>
    </hardware>
    <joint name="openarm_right_joint1">
      <command_interface name="position"/>
      <command_interface name="velocity"/>
      <command_interface name="effort"/>
      <state_interface name="position">
        <param name="initial_value">0.0</param>
      </state_interface>
      <state_interface name="velocity">
        <param name="initial_value">0.0</param>
      </state_interface>
      <state_interface name="effort">
        <param name="initial_value">0.0</param>
      </state_interface>
    </joint>
    <joint name="openarm_right_joint2">
      <command_interface name="position"/>
      <command_interface name="velocity"/>
      <command_interface name="effort"/>
      <state_interface name="position">
        <param name="initial_value">0.0</param>
      </state_interface>
      <state_interface name="velocity">
        <param name="initial_value">0.0</param>
      </state_interface>
      <state_interface name="effort">
        <param name="initial_value">0.0</param>
      </state_interface>
    </joint>
    <joint name="openarm_right_joint3">
      <command_interface name="position"/>
      <command_interface name="velocity"/>
      <command_interface name="effort"/>
      <state_interface name="position">
        <param name="initial_value">0.0</param>
      </state_interface>
      <state_interface name="velocity">
        <param name="initial_value">0.0</param>
      </state_interface>
      <state_interface name="effort">
        <param name="initial_value">0.0</param>
      </state_interface>
    </joint>
    <joint name="openarm_right_joint4">
      <command_interface name="position"/>
      <command_interface name="velocity"/>
      <command_interface name="effort"/>
      <state_interface name="position">
        <param name="initial_value">0.0</param>
      </state_interface>
      <state_interface name="velocity">
        <param name="initial_value">0.0</param>
      </state_interface>
      <state_interface name="effort">
        <param name="initial_value">0.0</param>
      </state_interface>
    </joint>
    <joint name="openarm_right_joint5">
      <command_interface name="position"/>
      <command_interface name="velocity"/>
      <command_interface name="effort"/>
      <state_interface name="position">
        <param name="initial_value">0.0</param>
      </state_interface>
      <state_interface name="velocity">
        <param name="initial_value">0.0</param>
      </state_interface>
      <state_interface name="effort">
        <param name="initial_value">0.0</param>
      </state_interface>
    </joint>
    <joint name="openarm_right_joint6">
      <command_interface name="position"/>
      <command_interface name="velocity"/>
      <command_interface name="effort"/>
      <state_interface name="position">
        <param name="initial_value">0.0</param>
      </state_interface>
      <state_interface name="velocity">
        <param name="initial_value">0.0</param>
      </state_interface>
      <state_interface name="effort">
        <param name="initial_value">0.0</param>
      </state_interface>
    </joint>
    <joint name="openarm_right_joint7">
      <command_interface name="position"/>
      <command_interface name="velocity"/>
      <command_interface name="effort"/>
      <state_interface name="position">
        <param name="initial_value">0.0</param>
      </state_interface>
      <state_interface name="velocity">
        <param name="initial_value">0.0</param>
      </state_interface>
      <state_interface name="effort">
        <param name="initial_value">0.0</param>
      </state_interface>
    </joint>
    <joint name="openarm_right_finger_joint1">
      <command_interface name="position"/>
      <command_interface name="velocity"/>
      <command_interface name="effort"/>
      <state_interface name="position">
        <param name="initial_value">0.0</param>
      </state_interface>
      <state_interface name="velocity">
        <param name="initial_value">0.0</param>
      </state_interface>
      <state_interface name="effort">
        <param name="initial_value">0.0</param>
      </state_interface>
    </joint>
    <!-- <joint name="openarm_${right_arm_prefix}finger_joint2">
        <param name="mimic">openarm_${right_arm_prefix}finger_joint1</param>
        <param name="multiplier">${right_finger_mimic_multiplier}</param>
        <command_interface name="position"/>
        <state_interface name="position">
          <param name="initial_value">0.0</param>
        </state_interface>
      </joint> -->
  </ros2_control>
</robot>
