<?xml version="1.0" ?>
<!-- =================================================================================== -->
<!-- |    This document was autogenerated by xacro from ../openarm_v20.urdf.xacro      | -->
<!-- |    EDITING THIS FILE BY HAND IS NOT RECOMMENDED                                 | -->
<!-- =================================================================================== -->
<robot name="openarm_v20">
  <link name="world"/>
  <link name="openarm_body_link0">
    <visual name="openarm_body_link0_visual">
      <origin rpy="0.0 0.0 0.0" xyz="0.0 0.0 0.0"/>
      <geometry>
        <mesh filename="package://openarm_description/assets/robot/openarm_v2.0/meshes/body/visual/body_link0.dae" scale="0.001 0.001 0.001"/>
      </geometry>
      <material name="openarm_body_link0_material">
        <color rgba="0.752941176470588 0.752941176470588 0.752941176470588 1"/>
      </material>
    </visual>
    <collision name="openarm_body_link0_collision">
      <origin rpy="0.0 0.0 0.0" xyz="0.0 0.0 0.0"/>
      <geometry>
        <mesh filename="package://openarm_description/assets/robot/openarm_v2.0/meshes/body/collision/body_link0_symp.stl" scale="0.001 0.001 0.001"/>
      </geometry>
    </collision>
    <inertial>
      <origin rpy="0 0 0" xyz="0 0 0"/>
      <mass value="13.89"/>
      <inertia ixx="1.653" ixy="0.0" ixz="0.0" iyy="1.653" iyz="0.0" izz="0.051"/>
    </inertial>
  </link>
  <joint name="openarm_body_link0_mount_joint" type="fixed">
    <origin rpy="0.0 0.0 0.0" xyz="0.0 0.0 0.0"/>
    <parent link="world"/>
    <child link="openarm_body_link0"/>
  </joint>
  <link name="openarm_left_base_link">
    <visual name="openarm_left_base_link_visual">
      <origin rpy="0 0 0" xyz="0 0 0"/>
      <geometry>
        <mesh filename="package://openarm_description/assets/robot/openarm_v2.0/meshes/arm/visual/base_link.dae" scale="1 -1 1"/>
      </geometry>
      <material name="openarm_left_base_link_material">
        <color rgba="0.752941176470588 0.752941176470588 0.752941176470588 1"/>
      </material>
    </visual>
    <collision name="openarm_left_base_link_collision">
      <origin rpy="0 0 0" xyz="0 0 0"/>
      <geometry>
        <mesh filename="package://openarm_description/assets/robot/openarm_v2.0/meshes/arm/collision/base_link.stl" scale="1 -1 1"/>
      </geometry>
    </collision>
    <inertial>
      <origin rpy="0 0 0" xyz="0.00253123748061566 0.0258185540330169 2.70658291858903e-05"/>
      <mass value="1.1432284943239561"/>
      <inertia ixx="0.00113607806226198" ixy="-3.81487993180929e-07" ixz="1.09161247709715e-08" iyy="0.00159935208714031" iyz="-2.7521421737084e-08" izz="0.000750541980863571"/>
    </inertial>
  </link>
  <joint name="openarm_left_base_link_mount_joint" type="fixed">
    <origin rpy="0.0 0.0 0.0" xyz="0.0 0.031 0.698"/>
    <parent link="openarm_body_link0"/>
    <child link="openarm_left_base_link"/>
  </joint>
  <link name="openarm_left_link1">
    <visual name="openarm_left_link1_visual">
      <origin rpy="0 0 0" xyz="0 0 0"/>
      <geometry>
        <mesh filename="package://openarm_description/assets/robot/openarm_v2.0/meshes/arm/visual/link1.dae" scale="1 -1 1"/>
      </geometry>
      <material name="openarm_left_link1_material">
        <color rgba="0.752941176470588 0.752941176470588 0.752941176470588 1"/>
      </material>
    </visual>
    <collision name="openarm_left_link1_collision">
      <origin rpy="0 0 0" xyz="0 0 0"/>
      <geometry>
        <mesh filename="package://openarm_description/assets/robot/openarm_v2.0/meshes/arm/collision/link1.stl" scale="1 -1 1"/>
      </geometry>
    </collision>
    <inertial>
      <origin rpy="0 0 0" xyz="0.000900350355624244 0.0444659716892874 2.88441021165683e-05"/>
      <mass value="1.1416684646202298"/>
      <inertia ixx="0.0010943212038551" ixy="-9.41628673674543e-06" ixz="4.53422182483102e-08" iyy="0.000759199728161993" iyz="-6.66755698859637e-08" izz="0.000670659201019629"/>
    </inertial>
  </link>
  <joint name="openarm_left_joint1" type="revolute">
    <origin rpy="0 0 0" xyz="0 0.0625 0"/>
    <parent link="openarm_left_base_link"/>
    <child link="openarm_left_link1"/>
    <axis xyz="0 1 0"/>
    <limit effort="40" lower="-3.4907" upper="1.3963" velocity="16.755"/>
  </joint>
  <link name="openarm_left_link2">
    <visual name="openarm_left_link2_visual">
      <origin rpy="0 0 0" xyz="0 0 0"/>
      <geometry>
        <mesh filename="package://openarm_description/assets/robot/openarm_v2.0/meshes/arm/visual/link2.dae" scale="1 -1 1"/>
      </geometry>
      <material name="openarm_left_link2_material">
        <color rgba="0.752941176470588 0.752941176470588 0.752941176470588 1"/>
      </material>
    </visual>
    <collision name="openarm_left_link2_collision">
      <origin rpy="0 0 0" xyz="0 0 0"/>
      <geometry>
        <mesh filename="package://openarm_description/assets/robot/openarm_v2.0/meshes/arm/collision/link2.stl" scale="1 -1 1"/>
      </geometry>
    </collision>
    <inertial>
      <origin rpy="0 0 0" xyz="-0.0247184924346635 -7.60578399428002e-08 -0.0312643102292087"/>
      <mass value="0.2775092746011571"/>
      <inertia ixx="0.000153588833784759" ixy="2.94422592188677e-10" ixz="5.21056076779068e-06" iyy="0.000113062180225725" iyz="-3.75816911469744e-10" izz="8.22999351863579e-05"/>
    </inertial>
  </link>
  <joint name="openarm_left_joint2" type="revolute">
    <origin rpy="0 0 0" xyz="0 0.0600000000000001 0"/>
    <parent link="openarm_left_link1"/>
    <child link="openarm_left_link2"/>
    <axis xyz="-1 0 0"/>
    <limit effort="40" lower="-3.3161" upper="0.17453" velocity="16.755"/>
  </joint>
  <link name="openarm_left_link3">
    <visual name="openarm_left_link3_visual">
      <origin rpy="0 0 0" xyz="0 0 0"/>
      <geometry>
        <mesh filename="package://openarm_description/assets/robot/openarm_v2.0/meshes/arm/visual/link3.dae" scale="1 1 1"/>
      </geometry>
      <material name="openarm_left_link3_material">
        <color rgba="0.752941176470588 0.752941176470588 0.752941176470588 1"/>
      </material>
    </visual>
    <collision name="openarm_left_link3_collision">
      <origin rpy="0 0 0" xyz="0 0 0"/>
      <geometry>
        <mesh filename="package://openarm_description/assets/robot/openarm_v2.0/meshes/arm/collision/link3.stl" scale="1 1 1"/>
      </geometry>
    </collision>
    <inertial>
      <origin rpy="0 0 0" xyz="-0.00300861804638783 -0.000514813312550808 -0.109368241429434"/>
      <mass value="1.073863338202347"/>
      <inertia ixx="0.00128939636591746" ixy="-2.29951046666492e-07" ixz="-6.76161926984358e-05" iyy="0.00114018992179734" iyz="-1.06260802872572e-05" izz="0.000559765478676303"/>
    </inertial>
  </link>
  <joint name="openarm_left_joint3" type="revolute">
    <origin rpy="0 0 0" xyz="0 0 -0.0662500000000008"/>
    <parent link="openarm_left_link2"/>
    <child link="openarm_left_link3"/>
    <axis xyz="0 0 -1"/>
    <limit effort="27" lower="-1.5708" upper="1.5708" velocity="5.4454"/>
  </joint>
  <link name="openarm_left_link4">
    <visual name="openarm_left_link4_visual">
      <origin rpy="0 0 0" xyz="0 0 0"/>
      <geometry>
        <mesh filename="package://openarm_description/assets/robot/openarm_v2.0/meshes/arm/visual/link4.dae" scale="1 1 1"/>
      </geometry>
      <material name="openarm_left_link4_material">
        <color rgba="0.752941176470588 0.752941176470588 0.752941176470588 1"/>
      </material>
    </visual>
    <collision name="openarm_left_link4_collision">
      <origin rpy="0 0 0" xyz="0 0 0"/>
      <geometry>
        <mesh filename="package://openarm_description/assets/robot/openarm_v2.0/meshes/arm/collision/link4.stl" scale="1 1 1"/>
      </geometry>
    </collision>
    <inertial>
      <origin rpy="0 0 0" xyz="-0.00310326243752606 -0.00136538979048502 -0.0574601379354351"/>
      <mass value="0.6348534566833373"/>
      <inertia ixx="0.0004690036047182" ixy="5.63626910265645e-06" ixz="-1.77877991597693e-06" iyy="0.000433926270522842" iyz="3.41757797773822e-06" izz="0.000245211429759716"/>
    </inertial>
  </link>
  <joint name="openarm_left_joint4" type="revolute">
    <origin rpy="0 0 0" xyz="0 0 -0.15375"/>
    <parent link="openarm_left_link3"/>
    <child link="openarm_left_link4"/>
    <axis xyz="0 -1 0"/>
    <limit effort="27" lower="0" upper="2.4435" velocity="5.4454"/>
  </joint>
  <link name="openarm_left_link5">
    <visual name="openarm_left_link5_visual">
      <origin rpy="0 0 0" xyz="0 0 0"/>
      <geometry>
        <mesh filename="package://openarm_description/assets/robot/openarm_v2.0/meshes/arm/visual/link5.dae" scale="1 -1 1"/>
      </geometry>
      <material name="openarm_left_link5_material">
        <color rgba="0.752941176470588 0.752941176470588 0.752941176470588 1"/>
      </material>
    </visual>
    <collision name="openarm_left_link5_collision">
      <origin rpy="0 0 0" xyz="0 0 0"/>
      <geometry>
        <mesh filename="package://openarm_description/assets/robot/openarm_v2.0/meshes/arm/collision/link5.stl" scale="1 -1 1"/>
      </geometry>
    </collision>
    <inertial>
      <origin rpy="0 0 0" xyz="-0.000737188580130584 0.000412406544351845 -0.047093829077211"/>
      <mass value="0.6156588026168502"/>
      <inertia ixx="0.000279653368752989" ixy="-3.31745289972445e-06" ixz="7.68097311403736e-07" iyy="0.000334599623120095" iyz="1.49934409279756e-07" izz="0.000176662464388138"/>
    </inertial>
  </link>
  <joint name="openarm_left_joint5" type="revolute">
    <origin rpy="0 0 0" xyz="0 0 -0.0955000000000005"/>
    <parent link="openarm_left_link4"/>
    <child link="openarm_left_link5"/>
    <axis xyz="0 0 -1"/>
    <limit effort="7" lower="-1.5708" upper="1.5708" velocity="20.944"/>
  </joint>
  <link name="openarm_left_link6">
    <visual name="openarm_left_link6_visual">
      <origin rpy="0 0 0" xyz="0 0 0"/>
      <geometry>
        <mesh filename="package://openarm_description/assets/robot/openarm_v2.0/meshes/arm/visual/link6.dae" scale="1 -1 1"/>
      </geometry>
      <material name="openarm_left_link6_material">
        <color rgba="0.752941176470588 0.752941176470588 0.752941176470588 1"/>
      </material>
    </visual>
    <collision name="openarm_left_link6_collision">
      <origin rpy="0 0 0" xyz="0 0 0"/>
      <geometry>
        <mesh filename="package://openarm_description/assets/robot/openarm_v2.0/meshes/arm/collision/link6.stl" scale="1 -1 1"/>
      </geometry>
    </collision>
    <inertial>
      <origin rpy="0 0 0" xyz="2.27438423593244e-05 -0.00068649602098908 5.44000494765995e-05"/>
      <mass value="0.475202773187987"/>
      <inertia ixx="0.000179275941446964" ixy="-6.58439346712228e-08" ixz="-3.37101167120887e-08" iyy="0.000136247512758587" iyz="-3.32253600295544e-08" izz="0.000135340695937386"/>
    </inertial>
  </link>
  <joint name="openarm_left_joint6" type="revolute">
    <origin rpy="0 0 0" xyz="0 0 -0.120499999999998"/>
    <parent link="openarm_left_link5"/>
    <child link="openarm_left_link6"/>
    <axis xyz="0 -1 0"/>
    <limit effort="7" lower="-0.7854" upper="0.7854" velocity="20.944"/>
  </joint>
  <joint name="openarm_left_joint7" type="revolute">
    <origin rpy="0 0 0" xyz="0 0 0"/>
    <parent link="openarm_left_link6"/>
    <child link="openarm_left_ee_base_link"/>
    <axis xyz="1 0 0"/>
    <limit effort="7" lower="-1.5708" upper="1.5708" velocity="20.944"/>
  </joint>
  <!-- The base link is emitted inline because its naming and frame-shift behavior differ from the finger links. -->
  <link name="openarm_left_ee_base_link">
    <visual name="openarm_left_ee_base_link_visual">
      <origin rpy="0.0 -0.0 0.0" xyz="0.0205 -0.0 0.0"/>
      <geometry>
        <mesh filename="package://openarm_description/assets/end_effector/pinch_gripper/meshes/visual/ee_base_link.dae" scale="1 -1 1"/>
      </geometry>
      <material name="openarm_left_ee_base_link_material">
        <color rgba="0.752941176470588 0.752941176470588 0.752941176470588 1"/>
      </material>
    </visual>
    <collision name="openarm_left_ee_base_link_collision">
      <origin rpy="0.0 -0.0 0.0" xyz="0.0205 -0.0 0.0"/>
      <geometry>
        <mesh filename="package://openarm_description/assets/end_effector/pinch_gripper/meshes/collision/ee_base_link.stl" scale="1 -1 1"/>
      </geometry>
    </collision>
    <inertial>
      <origin rpy="0.0 -0.0 0.0" xyz="0.0137902 -0.0084073 -0.05938"/>
      <mass value="0.52832"/>
      <inertia ixx="0.00021911" ixy="-4.1683e-06" ixz="1.4043e-06" iyy="0.00015627" iyz="1.5124e-06" izz="0.0001659"/>
    </inertial>
  </link>
  <link name="openarm_left_ee_link1">
    <visual name="openarm_left_ee_link1_visual">
      <origin rpy="0 0 0" xyz="0 0 0"/>
      <geometry>
        <mesh filename="package://openarm_description/assets/end_effector/pinch_gripper/meshes/visual/finger_inner.dae" scale="1 -1 1"/>
      </geometry>
      <material name="openarm_left_ee_link1_material">
        <color rgba="0.752941176470588 0.752941176470588 0.752941176470588 1"/>
      </material>
    </visual>
    <collision name="openarm_left_ee_link1_collision">
      <origin rpy="0 0 0" xyz="0 0 0"/>
      <geometry>
        <mesh filename="package://openarm_description/assets/end_effector/pinch_gripper/meshes/collision/finger_inner.stl" scale="1 -1 1"/>
      </geometry>
    </collision>
    <inertial>
      <origin rpy="0 0 0" xyz="-0.0124990911725494 -0.00176592789915655 -0.0241663193888537"/>
      <mass value="0.125979047366671"/>
      <inertia ixx="3.61105363396623e-05" ixy="-1.35880208293387e-06" ixz="7.13916341634141e-06" iyy="3.62137424319396e-05" iyz="3.60343788693423e-06" izz="1.74958961632907e-05"/>
    </inertial>
  </link>
  <link name="openarm_left_ee_link2">
    <visual name="openarm_left_ee_link2_visual">
      <origin rpy="0 0 0" xyz="0 0 0"/>
      <geometry>
        <mesh filename="package://openarm_description/assets/end_effector/pinch_gripper/meshes/visual/finger_outer.dae" scale="1 -1 1"/>
      </geometry>
      <material name="openarm_left_ee_link2_material">
        <color rgba="0.752941176470588 0.752941176470588 0.752941176470588 1"/>
      </material>
    </visual>
    <collision name="openarm_left_ee_link2_collision">
      <origin rpy="0 0 0" xyz="0 0 0"/>
      <geometry>
        <mesh filename="package://openarm_description/assets/end_effector/pinch_gripper/meshes/collision/finger_outer.stl" scale="1 -1 1"/>
      </geometry>
    </collision>
    <inertial>
      <origin rpy="0 0 0" xyz="-0.012796 0.0020183 -0.026792"/>
      <mass value="0.11372"/>
      <inertia ixx="3.4565e-05" ixy="1.3392e-06" ixz="7.1576e-06" iyy="3.5306e-05" iyz="-3.7172e-06" izz="1.6571e-05"/>
    </inertial>
  </link>
  <joint name="openarm_left_finger_joint1" type="revolute">
    <origin rpy="0.0 -0.0 0.0" xyz="-0.0014300000000005003 -0.0180000000000009 -0.0680000000000174"/>
    <parent link="openarm_left_ee_base_link"/>
    <child link="openarm_left_ee_link1"/>
    <axis xyz="-1 0 0"/>
    <limit effort="7" lower="0" upper="0.7854" velocity="5"/>
  </joint>
  <joint name="openarm_left_finger_joint2" type="revolute">
    <origin rpy="0.0 -0.0 0.0" xyz="-0.0014300000000005003 0.0180000000000012 -0.0680000000000215"/>
    <parent link="openarm_left_ee_base_link"/>
    <child link="openarm_left_ee_link2"/>
    <axis xyz="1 0 0"/>
    <limit effort="7" lower="0" upper="0.7854" velocity="5"/>
    <mimic joint="openarm_left_finger_joint1" multiplier="1" offset="0"/>
  </joint>
  <link name="openarm_right_base_link">
    <visual name="openarm_right_base_link_visual">
      <origin rpy="0 0 0" xyz="0 0 0"/>
      <geometry>
        <mesh filename="package://openarm_description/assets/robot/openarm_v2.0/meshes/arm/visual/base_link.dae" scale="1 1 1"/>
      </geometry>
      <material name="openarm_right_base_link_material">
        <color rgba="0.752941176470588 0.752941176470588 0.752941176470588 1"/>
      </material>
    </visual>
    <collision name="openarm_right_base_link_collision">
      <origin rpy="0 0 0" xyz="0 0 0"/>
      <geometry>
        <mesh filename="package://openarm_description/assets/robot/openarm_v2.0/meshes/arm/collision/base_link.stl" scale="1 1 1"/>
      </geometry>
    </collision>
    <inertial>
      <origin rpy="0 0 0" xyz="0.00253123748061566 -0.0258185540330169 2.70658291858903e-05"/>
      <mass value="1.1432284943239561"/>
      <inertia ixx="0.00113607806226198" ixy="3.81487993180929e-07" ixz="1.09161247709715e-08" iyy="0.00159935208714031" iyz="2.7521421737084e-08" izz="0.000750541980863571"/>
    </inertial>
  </link>
  <joint name="openarm_right_base_link_mount_joint" type="fixed">
    <origin rpy="0.0 0.0 0.0" xyz="0.0 -0.031 0.698"/>
    <parent link="openarm_body_link0"/>
    <child link="openarm_right_base_link"/>
  </joint>
  <link name="openarm_right_link1">
    <visual name="openarm_right_link1_visual">
      <origin rpy="0 0 0" xyz="0 0 0"/>
      <geometry>
        <mesh filename="package://openarm_description/assets/robot/openarm_v2.0/meshes/arm/visual/link1.dae" scale="1 1 1"/>
      </geometry>
      <material name="openarm_right_link1_material">
        <color rgba="0.752941176470588 0.752941176470588 0.752941176470588 1"/>
      </material>
    </visual>
    <collision name="openarm_right_link1_collision">
      <origin rpy="0 0 0" xyz="0 0 0"/>
      <geometry>
        <mesh filename="package://openarm_description/assets/robot/openarm_v2.0/meshes/arm/collision/link1.stl" scale="1 1 1"/>
      </geometry>
    </collision>
    <inertial>
      <origin rpy="0 0 0" xyz="0.000900350355624244 -0.0444659716892874 2.88441021165683e-05"/>
      <mass value="1.1416684646202298"/>
      <inertia ixx="0.0010943212038551" ixy="9.41628673674543e-06" ixz="4.53422182483102e-08" iyy="0.000759199728161993" iyz="6.66755698859637e-08" izz="0.000670659201019629"/>
    </inertial>
  </link>
  <joint name="openarm_right_joint1" type="revolute">
    <origin rpy="0 0 0" xyz="0 -0.0625 0"/>
    <parent link="openarm_right_base_link"/>
    <child link="openarm_right_link1"/>
    <axis xyz="0 -1 0"/>
    <limit effort="40" lower="-1.3963" upper="3.4907" velocity="16.755"/>
  </joint>
  <link name="openarm_right_link2">
    <visual name="openarm_right_link2_visual">
      <origin rpy="0 0 0" xyz="0 0 0"/>
      <geometry>
        <mesh filename="package://openarm_description/assets/robot/openarm_v2.0/meshes/arm/visual/link2.dae" scale="1 1 1"/>
      </geometry>
      <material name="openarm_right_link2_material">
        <color rgba="0.752941176470588 0.752941176470588 0.752941176470588 1"/>
      </material>
    </visual>
    <collision name="openarm_right_link2_collision">
      <origin rpy="0 0 0" xyz="0 0 0"/>
      <geometry>
        <mesh filename="package://openarm_description/assets/robot/openarm_v2.0/meshes/arm/collision/link2.stl" scale="1 1 1"/>
      </geometry>
    </collision>
    <inertial>
      <origin rpy="0 0 0" xyz="-0.0247184924346635 7.60578399428002e-08 -0.0312643102292087"/>
      <mass value="0.2775092746011571"/>
      <inertia ixx="0.000153588833784759" ixy="-2.94422592188677e-10" ixz="5.21056076779068e-06" iyy="0.000113062180225725" iyz="3.75816911469744e-10" izz="8.22999351863579e-05"/>
    </inertial>
  </link>
  <joint name="openarm_right_joint2" type="revolute">
    <origin rpy="0 0 0" xyz="0 -0.0600000000000001 0"/>
    <parent link="openarm_right_link1"/>
    <child link="openarm_right_link2"/>
    <axis xyz="-1 0 0"/>
    <limit effort="40" lower="-0.17453" upper="3.3161" velocity="16.755"/>
  </joint>
  <link name="openarm_right_link3">
    <visual name="openarm_right_link3_visual">
      <origin rpy="0 0 0" xyz="0 0 0"/>
      <geometry>
        <mesh filename="package://openarm_description/assets/robot/openarm_v2.0/meshes/arm/visual/link3.dae" scale="1 1 1"/>
      </geometry>
      <material name="openarm_right_link3_material">
        <color rgba="0.752941176470588 0.752941176470588 0.752941176470588 1"/>
      </material>
    </visual>
    <collision name="openarm_right_link3_collision">
      <origin rpy="0 0 0" xyz="0 0 0"/>
      <geometry>
        <mesh filename="package://openarm_description/assets/robot/openarm_v2.0/meshes/arm/collision/link3.stl" scale="1 1 1"/>
      </geometry>
    </collision>
    <inertial>
      <origin rpy="0 0 0" xyz="-0.00300861804638783 -0.000514813312550808 -0.109368241429434"/>
      <mass value="1.073863338202347"/>
      <inertia ixx="0.00128939636591746" ixy="-2.29951046666492e-07" ixz="-6.76161926984358e-05" iyy="0.00114018992179734" iyz="-1.06260802872572e-05" izz="0.000559765478676303"/>
    </inertial>
  </link>
  <joint name="openarm_right_joint3" type="revolute">
    <origin rpy="0 0 0" xyz="0 0 -0.0662500000000008"/>
    <parent link="openarm_right_link2"/>
    <child link="openarm_right_link3"/>
    <axis xyz="0 0 -1"/>
    <limit effort="27" lower="-1.5708" upper="1.5708" velocity="5.4454"/>
  </joint>
  <link name="openarm_right_link4">
    <visual name="openarm_right_link4_visual">
      <origin rpy="0 0 0" xyz="0 0 0"/>
      <geometry>
        <mesh filename="package://openarm_description/assets/robot/openarm_v2.0/meshes/arm/visual/link4.dae" scale="1 1 1"/>
      </geometry>
      <material name="openarm_right_link4_material">
        <color rgba="0.752941176470588 0.752941176470588 0.752941176470588 1"/>
      </material>
    </visual>
    <collision name="openarm_right_link4_collision">
      <origin rpy="0 0 0" xyz="0 0 0"/>
      <geometry>
        <mesh filename="package://openarm_description/assets/robot/openarm_v2.0/meshes/arm/collision/link4.stl" scale="1 1 1"/>
      </geometry>
    </collision>
    <inertial>
      <origin rpy="0 0 0" xyz="-0.00310326243752606 -0.00136538979048502 -0.0574601379354351"/>
      <mass value="0.6348534566833373"/>
      <inertia ixx="0.0004690036047182" ixy="5.63626910265645e-06" ixz="-1.77877991597693e-06" iyy="0.000433926270522842" iyz="3.41757797773822e-06" izz="0.000245211429759716"/>
    </inertial>
  </link>
  <joint name="openarm_right_joint4" type="revolute">
    <origin rpy="0 0 0" xyz="0 0 -0.15375"/>
    <parent link="openarm_right_link3"/>
    <child link="openarm_right_link4"/>
    <axis xyz="0 -1 0"/>
    <limit effort="27" lower="0" upper="2.4435" velocity="5.4454"/>
  </joint>
  <link name="openarm_right_link5">
    <visual name="openarm_right_link5_visual">
      <origin rpy="0 0 0" xyz="0 0 0"/>
      <geometry>
        <mesh filename="package://openarm_description/assets/robot/openarm_v2.0/meshes/arm/visual/link5.dae" scale="1 1 1"/>
      </geometry>
      <material name="openarm_right_link5_material">
        <color rgba="0.752941176470588 0.752941176470588 0.752941176470588 1"/>
      </material>
    </visual>
    <collision name="openarm_right_link5_collision">
      <origin rpy="0 0 0" xyz="0 0 0"/>
      <geometry>
        <mesh filename="package://openarm_description/assets/robot/openarm_v2.0/meshes/arm/collision/link5.stl" scale="1 1 1"/>
      </geometry>
    </collision>
    <inertial>
      <origin rpy="0 0 0" xyz="-0.000737188580130584 -0.000412406544351845 -0.047093829077211"/>
      <mass value="0.6156588026168502"/>
      <inertia ixx="0.000279653368752989" ixy="3.31745289972445e-06" ixz="7.68097311403736e-07" iyy="0.000334599623120095" iyz="-1.49934409279756e-07" izz="0.000176662464388138"/>
    </inertial>
  </link>
  <joint name="openarm_right_joint5" type="revolute">
    <origin rpy="0 0 0" xyz="0 0 -0.0955000000000005"/>
    <parent link="openarm_right_link4"/>
    <child link="openarm_right_link5"/>
    <axis xyz="0 0 -1"/>
    <limit effort="7" lower="-1.5708" upper="1.5708" velocity="20.944"/>
  </joint>
  <link name="openarm_right_link6">
    <visual name="openarm_right_link6_visual">
      <origin rpy="0 0 0" xyz="0 0 0"/>
      <geometry>
        <mesh filename="package://openarm_description/assets/robot/openarm_v2.0/meshes/arm/visual/link6.dae" scale="1 1 1"/>
      </geometry>
      <material name="openarm_right_link6_material">
        <color rgba="0.752941176470588 0.752941176470588 0.752941176470588 1"/>
      </material>
    </visual>
    <collision name="openarm_right_link6_collision">
      <origin rpy="0 0 0" xyz="0 0 0"/>
      <geometry>
        <mesh filename="package://openarm_description/assets/robot/openarm_v2.0/meshes/arm/collision/link6.stl" scale="1 1 1"/>
      </geometry>
    </collision>
    <inertial>
      <origin rpy="0 0 0" xyz="2.27438423593244e-05 0.00068649602098908 5.44000494765995e-05"/>
      <mass value="0.475202773187987"/>
      <inertia ixx="0.000179275941446964" ixy="6.58439346712228e-08" ixz="-3.37101167120887e-08" iyy="0.000136247512758587" iyz="3.32253600295544e-08" izz="0.000135340695937386"/>
    </inertial>
  </link>
  <joint name="openarm_right_joint6" type="revolute">
    <origin rpy="0 0 0" xyz="0 0 -0.120499999999998"/>
    <parent link="openarm_right_link5"/>
    <child link="openarm_right_link6"/>
    <axis xyz="0 1 0"/>
    <limit effort="7" lower="-0.7854" upper="0.7854" velocity="20.944"/>
  </joint>
  <joint name="openarm_right_joint7" type="revolute">
    <origin rpy="0 0 0" xyz="0 0 0"/>
    <parent link="openarm_right_link6"/>
    <child link="openarm_right_ee_base_link"/>
    <axis xyz="1 0 0"/>
    <limit effort="7" lower="-1.5708" upper="1.5708" velocity="20.944"/>
  </joint>
  <!-- The base link is emitted inline because its naming and frame-shift behavior differ from the finger links. -->
  <link name="openarm_right_ee_base_link">
    <visual name="openarm_right_ee_base_link_visual">
      <origin rpy="0.0 -0.0 0.0" xyz="0.0205 0.0 0.0"/>
      <geometry>
        <mesh filename="package://openarm_description/assets/end_effector/pinch_gripper/meshes/visual/ee_base_link.dae" scale="1 1 1"/>
      </geometry>
      <material name="openarm_right_ee_base_link_material">
        <color rgba="0.752941176470588 0.752941176470588 0.752941176470588 1"/>
      </material>
    </visual>
    <collision name="openarm_right_ee_base_link_collision">
      <origin rpy="0.0 -0.0 0.0" xyz="0.0205 0.0 0.0"/>
      <geometry>
        <mesh filename="package://openarm_description/assets/end_effector/pinch_gripper/meshes/collision/ee_base_link.stl" scale="1 1 1"/>
      </geometry>
    </collision>
    <inertial>
      <origin rpy="0.0 -0.0 0.0" xyz="0.0137902 0.0084073 -0.05938"/>
      <mass value="0.52832"/>
      <inertia ixx="0.00021911" ixy="4.1683e-06" ixz="1.4043e-06" iyy="0.00015627" iyz="-1.5124e-06" izz="0.0001659"/>
    </inertial>
  </link>
  <link name="openarm_right_ee_link1">
    <visual name="openarm_right_ee_link1_visual">
      <origin rpy="0 0 0" xyz="0 0 0"/>
      <geometry>
        <mesh filename="package://openarm_description/assets/end_effector/pinch_gripper/meshes/visual/finger_inner.dae" scale="1 1 1"/>
      </geometry>
      <material name="openarm_right_ee_link1_material">
        <color rgba="0.752941176470588 0.752941176470588 0.752941176470588 1"/>
      </material>
    </visual>
    <collision name="openarm_right_ee_link1_collision">
      <origin rpy="0 0 0" xyz="0 0 0"/>
      <geometry>
        <mesh filename="package://openarm_description/assets/end_effector/pinch_gripper/meshes/collision/finger_inner.stl" scale="1 1 1"/>
      </geometry>
    </collision>
    <inertial>
      <origin rpy="0 0 0" xyz="-0.0124990911725494 0.00176592789915655 -0.0241663193888537"/>
      <mass value="0.125979047366671"/>
      <inertia ixx="3.61105363396623e-05" ixy="1.35880208293387e-06" ixz="7.13916341634141e-06" iyy="3.62137424319396e-05" iyz="-3.60343788693423e-06" izz="1.74958961632907e-05"/>
    </inertial>
  </link>
  <link name="openarm_right_ee_link2">
    <visual name="openarm_right_ee_link2_visual">
      <origin rpy="0 0 0" xyz="0 0 0"/>
      <geometry>
        <mesh filename="package://openarm_description/assets/end_effector/pinch_gripper/meshes/visual/finger_outer.dae" scale="1 1 1"/>
      </geometry>
      <material name="openarm_right_ee_link2_material">
        <color rgba="0.752941176470588 0.752941176470588 0.752941176470588 1"/>
      </material>
    </visual>
    <collision name="openarm_right_ee_link2_collision">
      <origin rpy="0 0 0" xyz="0 0 0"/>
      <geometry>
        <mesh filename="package://openarm_description/assets/end_effector/pinch_gripper/meshes/collision/finger_outer.stl" scale="1 1 1"/>
      </geometry>
    </collision>
    <inertial>
      <origin rpy="0 0 0" xyz="-0.012796 -0.0020183 -0.026792"/>
      <mass value="0.11372"/>
      <inertia ixx="3.4565e-05" ixy="-1.3392e-06" ixz="7.1576e-06" iyy="3.5306e-05" iyz="3.7172e-06" izz="1.6571e-05"/>
    </inertial>
  </link>
  <joint name="openarm_right_finger_joint1" type="revolute">
    <origin rpy="0.0 -0.0 0.0" xyz="-0.0014300000000005003 0.0180000000000009 -0.0680000000000174"/>
    <parent link="openarm_right_ee_base_link"/>
    <child link="openarm_right_ee_link1"/>
    <axis xyz="-1 0 0"/>
    <limit effort="7" lower="-0.7854" upper="0" velocity="5"/>
  </joint>
  <joint name="openarm_right_finger_joint2" type="revolute">
    <origin rpy="0.0 -0.0 0.0" xyz="-0.0014300000000005003 -0.0180000000000012 -0.0680000000000215"/>
    <parent link="openarm_right_ee_base_link"/>
    <child link="openarm_right_ee_link2"/>
    <axis xyz="1 0 0"/>
    <limit effort="7" lower="-0.7854" upper="0" velocity="5"/>
    <mimic joint="openarm_right_finger_joint1" multiplier="1" offset="0"/>
  </joint>
  <ros2_control name="openarm_left_hardware_interface" type="system">
    <hardware>
      <param name="arm_type">v20</param>
      <plugin>mock_components/GenericSystem</plugin>
      <param name="fake_sensor_commands">False</param>
      <param name="state_following_offset">0.0</param>
    </hardware>
    <joint name="openarm_left_joint1">
      <command_interface name="position"/>
      <command_interface name="velocity"/>
      <command_interface name="effort"/>
      <state_interface name="position">
        <param name="initial_value">0.0</param>
      </state_interface>
      <state_interface name="velocity">
        <param name="initial_value">0.0</param>
      </state_interface>
      <state_interface name="effort">
        <param name="initial_value">0.0</param>
      </state_interface>
    </joint>
    <joint name="openarm_left_joint2">
      <command_interface name="position"/>
      <command_interface name="velocity"/>
      <command_interface name="effort"/>
      <state_interface name="position">
        <param name="initial_value">0.0</param>
      </state_interface>
      <state_interface name="velocity">
        <param name="initial_value">0.0</param>
      </state_interface>
      <state_interface name="effort">
        <param name="initial_value">0.0</param>
      </state_interface>
    </joint>
    <joint name="openarm_left_joint3">
      <command_interface name="position"/>
      <command_interface name="velocity"/>
      <command_interface name="effort"/>
      <state_interface name="position">
        <param name="initial_value">0.0</param>
      </state_interface>
      <state_interface name="velocity">
        <param name="initial_value">0.0</param>
      </state_interface>
      <state_interface name="effort">
        <param name="initial_value">0.0</param>
      </state_interface>
    </joint>
    <joint name="openarm_left_joint4">
      <command_interface name="position"/>
      <command_interface name="velocity"/>
      <command_interface name="effort"/>
      <state_interface name="position">
        <param name="initial_value">0.0</param>
      </state_interface>
      <state_interface name="velocity">
        <param name="initial_value">0.0</param>
      </state_interface>
      <state_interface name="effort">
        <param name="initial_value">0.0</param>
      </state_interface>
    </joint>
    <joint name="openarm_left_joint5">
      <command_interface name="position"/>
      <command_interface name="velocity"/>
      <command_interface name="effort"/>
      <state_interface name="position">
        <param name="initial_value">0.0</param>
      </state_interface>
      <state_interface name="velocity">
        <param name="initial_value">0.0</param>
      </state_interface>
      <state_interface name="effort">
        <param name="initial_value">0.0</param>
      </state_interface>
    </joint>
    <joint name="openarm_left_joint6">
      <command_interface name="position"/>
      <command_interface name="velocity"/>
      <command_interface name="effort"/>
      <state_interface name="position">
        <param name="initial_value">0.0</param>
      </state_interface>
      <state_interface name="velocity">
        <param name="initial_value">0.0</param>
      </state_interface>
      <state_interface name="effort">
        <param name="initial_value">0.0</param>
      </state_interface>
    </joint>
    <joint name="openarm_left_joint7">
      <command_interface name="position"/>
      <command_interface name="velocity"/>
      <command_interface name="effort"/>
      <state_interface name="position">
        <param name="initial_value">0.0</param>
      </state_interface>
      <state_interface name="velocity">
        <param name="initial_value">0.0</param>
      </state_interface>
      <state_interface name="effort">
        <param name="initial_value">0.0</param>
      </state_interface>
    </joint>
    <joint name="openarm_left_finger_joint1">
      <command_interface name="position"/>
      <command_interface name="velocity"/>
      <command_interface name="effort"/>
      <state_interface name="position">
        <param name="initial_value">0.0</param>
      </state_interface>
      <state_interface name="velocity">
        <param name="initial_value">0.0</param>
      </state_interface>
      <state_interface name="effort">
        <param name="initial_value">0.0</param>
      </state_interface>
    </joint>
    <!-- <joint name="openarm_${left_arm_prefix}finger_joint2">
        <param name="mimic">openarm_${left_arm_prefix}finger_joint1</param>
        <param name="multiplier">${left_finger_mimic_multiplier}</param>
        <command_interface name="position"/>
        <state_interface name="position">
          <param name="initial_value">0.0</param>
        </state_interface>
      </joint> -->
  </ros2_control>
  <ros2_control name="openarm_right_hardware_interface" type="system">
    <hardware>
      <param name="arm_type">v20</param>
      <plugin>mock_components/GenericSystem</plugin>
      <param name="fake_sensor_commands">False</param>
      <param name="state_following_offset">0.0</param>
    </hardware>
    <joint name="openarm_right_joint1">
      <command_interface name="position"/>
      <command_interface name="velocity"/>
      <command_interface name="effort"/>
      <state_interface name="position">
        <param name="initial_value">0.0</param>
      </state_interface>
      <state_interface name="velocity">
        <param name="initial_value">0.0</param>
      </state_interface>
      <state_interface name="effort">
        <param name="initial_value">0.0</param>
      </state_interface>
    </joint>
    <joint name="openarm_right_joint2">
      <command_interface name="position"/>
      <command_interface name="velocity"/>
      <command_interface name="effort"/>
      <state_interface name="position">
        <param name="initial_value">0.0</param>
      </state_interface>
      <state_interface name="velocity">
        <param name="initial_value">0.0</param>
      </state_interface>
      <state_interface name="effort">
        <param name="initial_value">0.0</param>
      </state_interface>
    </joint>
    <joint name="openarm_right_joint3">
      <command_interface name="position"/>
      <command_interface name="velocity"/>
      <command_interface name="effort"/>
      <state_interface name="position">
        <param name="initial_value">0.0</param>
      </state_interface>
      <state_interface name="velocity">
        <param name="initial_value">0.0</param>
      </state_interface>
      <state_interface name="effort">
        <param name="initial_value">0.0</param>
      </state_interface>
    </joint>
    <joint name="openarm_right_joint4">
      <command_interface name="position"/>
      <command_interface name="velocity"/>
      <command_interface name="effort"/>
      <state_interface name="position">
        <param name="initial_value">0.0</param>
      </state_interface>
      <state_interface name="velocity">
        <param name="initial_value">0.0</param>
      </state_interface>
      <state_interface name="effort">
        <param name="initial_value">0.0</param>
      </state_interface>
    </joint>
    <joint name="openarm_right_joint5">
      <command_interface name="position"/>
      <command_interface name="velocity"/>
      <command_interface name="effort"/>
      <state_interface name="position">
        <param name="initial_value">0.0</param>
      </state_interface>
      <state_interface name="velocity">
        <param name="initial_value">0.0</param>
      </state_interface>
      <state_interface name="effort">
        <param name="initial_value">0.0</param>
      </state_interface>
    </joint>
    <joint name="openarm_right_joint6">
      <command_interface name="position"/>
      <command_interface name="velocity"/>
      <command_interface name="effort"/>
      <state_interface name="position">
        <param name="initial_value">0.0</param>
      </state_interface>
      <state_interface name="velocity">
        <param name="initial_value">0.0</param>
      </state_interface>
      <state_interface name="effort">
        <param name="initial_value">0.0</param>
      </state_interface>
    </joint>
    <joint name="openarm_right_joint7">
      <command_interface name="position"/>
      <command_interface name="velocity"/>
      <command_interface name="effort"/>
      <state_interface name="position">
        <param name="initial_value">0.0</param>
      </state_interface>
      <state_interface name="velocity">
        <param name="initial_value">0.0</param>
      </state_interface>
      <state_interface name="effort">
        <param name="initial_value">0.0</param>
      </state_interface>
    </joint>
    <joint name="openarm_right_finger_joint1">
      <command_interface name="position"/>
      <command_interface name="velocity"/>
      <command_interface name="effort"/>
      <state_interface name="position">
        <param name="initial_value">0.0</param>
      </state_interface>
      <state_interface name="velocity">
        <param name="initial_value">0.0</param>
      </state_interface>
      <state_interface name="effort">
        <param name="initial_value">0.0</param>
      </state_interface>
    </joint>
    <!-- <joint name="openarm_${right_arm_prefix}finger_joint2">
        <param name="mimic">openarm_${right_arm_prefix}finger_joint1</param>
        <param name="multiplier">${right_finger_mimic_multiplier}</param>
        <command_interface name="position"/>
        <state_interface name="position">
          <param name="initial_value">0.0</param>
        </state_interface>
      </joint> -->
  </ros2_control>
</robot>
